<sdf version='1.6'>
  <world name='default'>
    <light name='sun' type='directional'>
      <cast_shadows>1</cast_shadows>
      <pose frame=''>0 0 10 0 -0 0</pose>
      <diffuse>0.8 0.8 0.8 1</diffuse>
      <specular>0.2 0.2 0.2 1</specular>
      <attenuation>
        <range>1000</range>
        <constant>0.9</constant>
        <linear>0.01</linear>
        <quadratic>0.001</quadratic>
      </attenuation>
      <direction>-0.5 0.1 -0.9</direction>
    </light>
    <model name='ground_plane'>
      <static>1</static>
      <link name='link'>
        <collision name='collision'>
          <geometry>
            <plane>
              <normal>0 0 1</normal>
              <size>100 100</size>
            </plane>
          </geometry>
          <surface>
            <friction>
              <ode>
                <mu>100</mu>
                <mu2>50</mu2>
              </ode>
              <torsional>
                <ode/>
              </torsional>
            </friction>
            <contact>
              <ode/>
            </contact>
            <bounce/>
          </surface>
          <max_contacts>10</max_contacts>
        </collision>
        <visual name='visual'>
          <cast_shadows>0</cast_shadows>
          <geometry>
            <plane>
              <normal>0 0 1</normal>
              <size>100 100</size>
            </plane>
          </geometry>
          <material>
            <script>
              <uri>file://media/materials/scripts/gazebo.material</uri>
              <name>Gazebo/Grey</name>
            </script>
          </material>
        </visual>
        <self_collide>0</self_collide>
        <enable_wind>0</enable_wind>
        <kinematic>0</kinematic>
      </link>
    </model>
    <model name='Dolly'>
      <pose frame=''>0 0 0.33 0 -0 0</pose>
      <link name='chassis'>
        <inertial>
          <mass>1</mass>
          <inertia>
            <ixx>0.0227</ixx>
            <ixy>0</ixy>
            <ixz>0</ixz>
            <iyy>0.0852</iyy>
            <iyz>0</iyz>
            <izz>0.1041</izz>
          </inertia>
          <pose frame=''>0 0 0 0 -0 0</pose>
        </inertial>
        <visual name='visual'>
          <geometry>
            <box>
              <size>1 0.5 0.15</size>
            </box>
          </geometry>
          <material>
            <script>
              <uri>model://dolly/materials/scripts</uri>
              <uri>model://dolly/materials/textures</uri>
              <name>Dolly/fur</name>
            </script>
          </material>
        </visual>
        <visual name='box'>
          <pose frame=''>0 0 0.08 0 -0 0.24</pose>
          <geometry>
            <mesh>
              <uri>model://cardboard_box/meshes/cardboard_box.dae</uri>
              <scale>1.25932 1.00745 0.755591</scale>
            </mesh>
          </geometry>
        </visual>
        <sensor name='sensor_ray' type='ray'>
          <pose frame=''>0.5 0 0 0 -0 0</pose>
          <ray>
            <scan>
              <horizontal>
                <samples>200</samples>
                <resolution>1</resolution>
                <min_angle>-1</min_angle>
                <max_angle>1</max_angle>
              </horizontal>
              <vertical>
                <samples>1</samples>
                <min_angle>0</min_angle>
                <max_angle>0</max_angle>
              </vertical>
            </scan>
            <range>
              <min>0.05</min>
              <max>10</max>
            </range>
          </ray>
          <always_on>1</always_on>
          <visualize>1</visualize>
          <update_rate>100</update_rate>
          <plugin name='laser' filename='libgazebo_ros_ray_sensor.so'>
            <ros>
              <namespace>/dolly</namespace>
              <remapping>~/out:=laser_scan</remapping>
            </ros>
            <output_type>sensor_msgs/LaserScan</output_type>
          </plugin>
        </sensor>
        <self_collide>0</self_collide>
        <enable_wind>0</enable_wind>
        <kinematic>0</kinematic>
      </link>
      <link name='caster'>
        <pose frame=''>-0.3 0 -0.125 0 -0 0</pose>
        <inertial>
          <mass>0.0415553</mass>
          <inertia>
            <ixx>7.97741e-05</ixx>
            <ixy>0</ixy>
            <ixz>0</ixz>
            <iyy>7.97741e-05</iyy>
            <iyz>0</iyz>
            <izz>7.97741e-05</izz>
          </inertia>
          <pose frame=''>0 0 0 0 -0 0</pose>
        </inertial>
        <visual name='visual'>
          <geometry>
            <sphere>
              <radius>0.1</radius>
            </sphere>
          </geometry>
          <material>
            <diffuse>0.5 0.5 0.5 1</diffuse>
            <ambient>0 0 0 1</ambient>
            <specular>1 1 1 1</specular>
            <emissive>0 0 0 1</emissive>
          </material>
        </visual>
        <collision name='collision'>
          <geometry>
            <sphere>
              <radius>0.1</radius>
            </sphere>
          </geometry>
          <surface>
            <friction>
              <ode>
                <mu>1</mu>
                <mu2>1</mu2>
                <slip1>0</slip1>
                <slip2>0</slip2>
              </ode>
              <torsional>
                <ode/>
              </torsional>
            </friction>
            <contact>
              <ode>
                <soft_cfm>0</soft_cfm>
                <soft_erp>0.2</soft_erp>
                <kp>1e+13</kp>
                <kd>1</kd>
                <max_vel>0.01</max_vel>
                <min_depth>0</min_depth>
              </ode>
            </contact>
            <bounce/>
          </surface>
          <max_contacts>10</max_contacts>
        </collision>
        <self_collide>0</self_collide>
        <enable_wind>0</enable_wind>
        <kinematic>0</kinematic>
      </link>
      <link name='left_wheel'>
        <pose frame=''>0.3 0.3 -0.075 -1.5707 0 0</pose>
        <inertial>
          <mass>0.5</mass>
          <inertia>
            <ixx>0.0029</ixx>
            <ixy>0</ixy>
            <ixz>0</ixz>
            <iyy>0.0029</iyy>
            <iyz>0</iyz>
            <izz>0.0056</izz>
          </inertia>
          <pose frame=''>0 0 0 0 -0 0</pose>
        </inertial>
        <visual name='visual'>
          <geometry>
            <cylinder>
              <radius>0.15</radius>
              <length>0.05</length>
            </cylinder>
          </geometry>
          <material>
            <diffuse>0.5 0.5 0.5 1</diffuse>
            <ambient>0 0 0 1</ambient>
            <specular>1 1 1 1</specular>
            <emissive>0 0 0 1</emissive>
          </material>
        </visual>
        <collision name='collision'>
          <geometry>
            <sphere>
              <radius>0.15</radius>
            </sphere>
          </geometry>
          <surface>
            <friction>
              <ode>
                <mu>1</mu>
                <mu2>1</mu2>
                <slip1>0</slip1>
                <slip2>0</slip2>
              </ode>
              <torsional>
                <ode/>
              </torsional>
            </friction>
            <contact>
              <ode>
                <soft_cfm>0</soft_cfm>
                <soft_erp>0.2</soft_erp>
                <kp>1e+13</kp>
                <kd>1</kd>
                <max_vel>0.01</max_vel>
                <min_depth>0.01</min_depth>
              </ode>
            </contact>
            <bounce/>
          </surface>
          <max_contacts>10</max_contacts>
        </collision>
        <self_collide>0</self_collide>
        <enable_wind>0</enable_wind>
        <kinematic>0</kinematic>
      </link>
      <link name='right_wheel'>
        <pose frame=''>0.3 -0.3 -0.075 -1.5707 0 0</pose>
        <inertial>
          <mass>0.5</mass>
          <inertia>
            <ixx>0.0029</ixx>
            <ixy>0</ixy>
            <ixz>0</ixz>
            <iyy>0.0029</iyy>
            <iyz>0</iyz>
            <izz>0.0056</izz>
          </inertia>
          <pose frame=''>0 0 0 0 -0 0</pose>
        </inertial>
        <visual name='visual'>
          <geometry>
            <cylinder>
              <radius>0.15</radius>
              <length>0.05</length>
            </cylinder>
          </geometry>
          <material>
            <diffuse>0.5 0.5 0.5 1</diffuse>
            <ambient>0 0 0 1</ambient>
            <specular>1 1 1 1</specular>
            <emissive>0 0 0 1</emissive>
          </material>
        </visual>
        <collision name='collision'>
          <geometry>
            <sphere>
              <radius>0.15</radius>
            </sphere>
          </geometry>
          <surface>
            <friction>
              <ode>
                <mu>1</mu>
                <mu2>1</mu2>
                <slip1>0</slip1>
                <slip2>0</slip2>
              </ode>
              <torsional>
                <ode/>
              </torsional>
            </friction>
            <contact>
              <ode>
                <soft_cfm>0</soft_cfm>
                <soft_erp>0.2</soft_erp>
                <kp>1e+13</kp>
                <kd>1</kd>
                <max_vel>0.01</max_vel>
                <min_depth>0.01</min_depth>
              </ode>
            </contact>
            <bounce/>
          </surface>
          <max_contacts>10</max_contacts>
        </collision>
        <self_collide>0</self_collide>
        <enable_wind>0</enable_wind>
        <kinematic>0</kinematic>
      </link>
      <link name='tail'>
        <pose frame=''>-0.52 0 0 -1.6 0 0</pose>
        <inertial>
          <mass>0.0254232</mass>
          <inertia>
            <ixx>1.528e-05</ixx>
            <ixy>0</ixy>
            <ixz>0</ixz>
            <iyy>1.528e-05</iyy>
            <iyz>0</iyz>
            <izz>3.45e-06</izz>
          </inertia>
          <pose frame=''>0 0 -0.04 0 -0 0</pose>
        </inertial>
        <visual name='visual'>
          <geometry>
            <cylinder>
              <radius>0.016468</radius>
              <length>0.08</length>
            </cylinder>
          </geometry>
          <material>
            <script>
              <uri>model://dolly/materials/scripts</uri>
              <uri>model://dolly/materials/textures</uri>
              <name>Dolly/fur</name>
            </script>
          </material>
        </visual>
        <self_collide>0</self_collide>
        <enable_wind>0</enable_wind>
        <kinematic>0</kinematic>
      </link>
      <joint name='left_wheel_joint' type='revolute'>
        <parent>chassis</parent>
        <child>left_wheel</child>
        <axis>
          <xyz>0 0 1</xyz>
          <limit>
            <lower>-1.79769e+308</lower>
            <upper>1.79769e+308</upper>
          </limit>
          <use_parent_model_frame>0</use_parent_model_frame>
          <dynamics>
            <spring_reference>0</spring_reference>
            <spring_stiffness>0</spring_stiffness>
          </dynamics>
        </axis>
      </joint>
      <joint name='right_wheel_joint' type='revolute'>
        <parent>chassis</parent>
        <child>right_wheel</child>
        <axis>
          <xyz>0 0 1</xyz>
          <limit>
            <lower>-1.79769e+308</lower>
            <upper>1.79769e+308</upper>
          </limit>
          <use_parent_model_frame>0</use_parent_model_frame>
          <dynamics>
            <spring_reference>0</spring_reference>
            <spring_stiffness>0</spring_stiffness>
          </dynamics>
        </axis>
      </joint>
      <joint name='caster_wheel' type='ball'>
        <parent>chassis</parent>
        <child>caster</child>
      </joint>
      <joint name='tail_joint' type='revolute'>
        <parent>chassis</parent>
        <child>tail</child>
        <pose frame=''>0 0 0.04 0 -0 0</pose>
        <axis>
          <xyz>1 0 0</xyz>
          <use_parent_model_frame>0</use_parent_model_frame>
          <limit>
            <lower>-1.79769e+308</lower>
            <upper>1.79769e+308</upper>
            <effort>-1</effort>
            <velocity>-1</velocity>
          </limit>
          <dynamics>
            <spring_reference>0</spring_reference>
            <spring_stiffness>0</spring_stiffness>
            <damping>0</damping>
            <friction>0</friction>
          </dynamics>
        </axis>
        <physics>
          <ode>
            <limit>
              <cfm>0</cfm>
              <erp>0.2</erp>
            </limit>
            <suspension>
              <cfm>0</cfm>
              <erp>0.2</erp>
            </suspension>
          </ode>
        </physics>
      </joint>
      <plugin name='diff_drive' filename='libgazebo_ros_diff_drive.so'>
        <ros>
          <namespace>/dolly</namespace>
        </ros>
        <left_joint>left_wheel_joint</left_joint>
        <right_joint>right_wheel_joint</right_joint>
        <wheel_separation>1.25</wheel_separation>
        <wheel_diameter>0.3</wheel_diameter>
        <max_wheel_torque>20</max_wheel_torque>
        <max_wheel_acceleration>1.0</max_wheel_acceleration>
        <publish_odom>1</publish_odom>
        <publish_odom_tf>1</publish_odom_tf>
        <odometry_frame>odom_demo</odometry_frame>
        <robot_base_frame>chassis</robot_base_frame>
      </plugin>
    </model>
    <model name='casual_female'>
      <static>1</static>
      <link name='link'>
        <collision name='box'>
          <pose frame=''>0 0 0.9 0 -0 0</pose>
          <geometry>
            <box>
              <size>0.76 0.33 1.77</size>
            </box>
          </geometry>
          <max_contacts>10</max_contacts>
          <surface>
            <contact>
              <ode/>
            </contact>
            <bounce/>
            <friction>
              <torsional>
                <ode/>
              </torsional>
              <ode/>
            </friction>
          </surface>
        </collision>
        <visual name='visual'>
          <pose frame=''>0 0 0.02 0.04 -0 0</pose>
          <geometry>
            <mesh>
              <uri>model://casual_female/meshes/casual_female.dae</uri>
            </mesh>
          </geometry>
        </visual>
        <self_collide>0</self_collide>
        <enable_wind>0</enable_wind>
        <kinematic>0</kinematic>
      </link>
      <pose frame=''>2 0 0.14 0 -0 1.5</pose>
    </model>
    <gravity>0 0 -9.8</gravity>
    <magnetic_field>6e-06 2.3e-05 -4.2e-05</magnetic_field>
    <atmosphere type='adiabatic'/>
    <physics name='default_physics' default='0' type='ode'>
      <max_step_size>0.001</max_step_size>
      <real_time_factor>1</real_time_factor>
      <real_time_update_rate>1000</real_time_update_rate>
    </physics>
    <scene>
      <ambient>0.4 0.4 0.4 1</ambient>
      <background>0.7 0.7 0.7 1</background>
      <shadows>1</shadows>
    </scene>
    <wind/>
    <spherical_coordinates>
      <surface_model>EARTH_WGS84</surface_model>
      <latitude_deg>0</latitude_deg>
      <longitude_deg>0</longitude_deg>
      <elevation>0</elevation>
      <heading_deg>0</heading_deg>
    </spherical_coordinates>
    <state world_name='default'>
      <sim_time>150 118000000</sim_time>
      <real_time>153 1968351</real_time>
      <wall_time>1594951148 577574839</wall_time>
      <iterations>150118</iterations>
      <model name='Dolly'>
        <pose frame=''>-0.015309 -0.000198 0.224806 3.3e-05 0.000632 0.000648</pose>
        <scale>1 1 1</scale>
        <link name='caster'>
          <pose frame=''>-0.315388 -0.000388 0.099996 0.037117 0.412891 0.007733</pose>
          <velocity>-0.000471 0.000104 -0.003835 -0.000436 0.002752 0</velocity>
          <acceleration>-0.747661 0.060092 -7.66488 0 -0 0</acceleration>
          <wrench>-0.031069 0.002497 -0.318516 0 -0 0</wrench>
        </link>
        <link name='chassis'>
          <pose frame=''>-0.015309 -0.000198 0.224806 3.3e-05 0.000632 0.000648</pose>
          <velocity>-0.001237 5.6e-05 -0.001816 3.2e-05 -0.005997 -0.000144</velocity>
          <acceleration>-2.27839 0.030635 -3.62785 0.043853 0.575729 -0.071975</acceleration>
          <wrench>-2.27839 0.030635 -3.62785 0 -0 0</wrench>
        </link>
        <link name='left_wheel'>
          <pose frame=''>0.284449 0.299999 0.149626 -1.57067 -0.101334 0.000635</pose>
          <velocity>-0.000823 8e-06 1e-06 -4.7e-05 -0.005499 -0.000143</velocity>
          <acceleration>-1.51023 0.002288 0.003821 -0.016873 1.04785 -0.138049</acceleration>
          <wrench>-0.755116 0.001144 0.00191 0 -0 0</wrench>
        </link>
        <link name='right_wheel'>
          <pose frame=''>0.284838 -0.300001 0.149606 -1.57067 -0.098766 0.000635</pose>
          <velocity>-0.000895 8e-06 -0 -5e-05 -0.00597 -0.000165</velocity>
          <acceleration>-1.5372 0.003018 0.003772 -0.023619 0.956407 -0.221073</acceleration>
          <wrench>-0.7686 0.001509 0.001886 0 -0 0</wrench>
        </link>
        <link name='tail'>
          <pose frame=''>-0.53536 0.079425 0.225885 1.61869 0.000631 0.000647</pose>
          <velocity>-0.001381 0.026318 -0.442288 1.61816 -0.012497 0.007466</velocity>
          <acceleration>-2.06981 -9.61112 -10.3706 0.800614 1.03094 -1.53671</acceleration>
          <wrench>-0.052621 -0.244345 -0.263653 0 -0 0</wrench>
        </link>
      </model>
      <model name='casual_female'>
        <pose frame=''>2 0 0.14 0 -0 1.5</pose>
        <scale>1 1 1</scale>
        <link name='link'>
          <pose frame=''>2 0 0.14 0 -0 1.5</pose>
          <velocity>0 0 0 0 -0 0</velocity>
          <acceleration>0 0 0 0 -0 0</acceleration>
          <wrench>0 0 0 0 -0 0</wrench>
        </link>
      </model>
      <model name='ground_plane'>
        <pose frame=''>0 0 0 0 -0 0</pose>
        <scale>1 1 1</scale>
        <link name='link'>
          <pose frame=''>0 0 0 0 -0 0</pose>
          <velocity>0 0 0 0 -0 0</velocity>
          <acceleration>0 0 0 0 -0 0</acceleration>
          <wrench>0 0 0 0 -0 0</wrench>
        </link>
      </model>
      <light name='sun'>
        <pose frame=''>0 0 10 0 -0 0</pose>
      </light>
    </state>
    <gui fullscreen='0'>
      <camera name='user_camera'>
        <pose frame=''>5 -5 2 0 0.275643 2.35619</pose>
        <view_controller>orbit</view_controller>
        <projection_type>perspective</projection_type>
      </camera>
    </gui>
  </world>
</sdf>
